Traceback (most recent call last):
  File "C:\Users\cgaur\anaconda3\Lib\site-packages\jupyter_cache\executors\utils.py", line 58, in single_nb_execution
    executenb(
  File "C:\Users\cgaur\anaconda3\Lib\site-packages\nbclient\client.py", line 1305, in execute
    return NotebookClient(nb=nb, resources=resources, km=km, **kwargs).execute()
           ^^^^^^^^^^^^^^^^^^^^^^^^^^^^^^^^^^^^^^^^^^^^^^^^^^^^^^^^^^^^^^^^^^^^^
  File "C:\Users\cgaur\anaconda3\Lib\site-packages\jupyter_core\utils\__init__.py", line 165, in wrapped
    return loop.run_until_complete(inner)
           ^^^^^^^^^^^^^^^^^^^^^^^^^^^^^^
  File "C:\Users\cgaur\anaconda3\Lib\asyncio\base_events.py", line 687, in run_until_complete
    return future.result()
           ^^^^^^^^^^^^^^^
  File "C:\Users\cgaur\anaconda3\Lib\site-packages\nbclient\client.py", line 705, in async_execute
    await self.async_execute_cell(
  File "C:\Users\cgaur\anaconda3\Lib\site-packages\nbclient\client.py", line 1058, in async_execute_cell
    await self._check_raise_for_error(cell, cell_index, exec_reply)
  File "C:\Users\cgaur\anaconda3\Lib\site-packages\nbclient\client.py", line 914, in _check_raise_for_error
    raise CellExecutionError.from_cell_and_msg(cell, exec_reply_content)
nbclient.exceptions.CellExecutionError: An error occurred while executing the following cell:
------------------

cursor.executemany('''
INSERT INTO country(country_id,country) values(?,?)
                   ''',tuples_for_insertion['countries'])

# Insert data for each table using the appropriate query
cursor.executemany('''
INSERT INTO EDUCATION (education_id, education, education_num)
VALUES (?, ?, ?)
''', tuples_for_insertion['education'])

cursor.executemany('''
INSERT INTO RACE (race_id, race)
VALUES (?, ?)
''', tuples_for_insertion['races'])

cursor.executemany('''
INSERT INTO OCCUPATION (occupation_id, occupation)
VALUES (?, ?)
''', tuples_for_insertion['occupations'])

cursor.executemany('''
INSERT INTO WORKCLASS (workclass_id, workclass)
VALUES (?, ?)
''', tuples_for_insertion['workclasses'])

cursor.executemany('''
INSERT INTO Marital_Status (marital_status_id, marital_status)
VALUES (?, ?)
''', tuples_for_insertion['marital_statuses'])

cursor.executemany('''
INSERT INTO Relationship (relationship_id, relationship)
VALUES (?, ?)
''', tuples_for_insertion['relationships'])

cursor.executemany('''
INSERT INTO Gender (gender_id, gender)
VALUES (?, ?)
''', tuples_for_insertion['genders'])

------------------


[1;31m---------------------------------------------------------------------------[0m
[1;31mIntegrityError[0m                            Traceback (most recent call last)
Cell [1;32mIn[6], line 1[0m
[1;32m----> 1[0m cursor[38;5;241m.[39mexecutemany([38;5;124m'''[39m
[0;32m      2[0m [38;5;124mINSERT INTO country(country_id,country) values(?,?)[39m
[0;32m      3[0m [38;5;124m                   [39m[38;5;124m'''[39m,tuples_for_insertion[[38;5;124m'[39m[38;5;124mcountries[39m[38;5;124m'[39m])
[0;32m      5[0m [38;5;66;03m# Insert data for each table using the appropriate query[39;00m
[0;32m      6[0m cursor[38;5;241m.[39mexecutemany([38;5;124m'''[39m
[0;32m      7[0m [38;5;124mINSERT INTO EDUCATION (education_id, education, education_num)[39m
[0;32m      8[0m [38;5;124mVALUES (?, ?, ?)[39m
[0;32m      9[0m [38;5;124m'''[39m, tuples_for_insertion[[38;5;124m'[39m[38;5;124meducation[39m[38;5;124m'[39m])

[1;31mIntegrityError[0m: UNIQUE constraint failed: COUNTRY.country_id

